Workbook

Sheet Week1
A1: Bond | C1: US Treasury 7-year
A2: Face Value | C2: 1000
A3: Coupon Rate | C3: 0.03875
A4: Maturity | C4: 47483
A5: Source | C5: US7Y: 3.80% -0.006 (0.00%) (cnbc.com)
C6: Week 1 | D6: Week 2 | E6: Week 3 | F6: Week 4 | G6: Week 5 | H6: Week 6 | I6: Week 7 | J6: Week 8 | K6: Week 9
A8: Yield | C8: 0.038 | D8: 0.0349 | E8: 0.03439 | F8: 0.03556 | G8: 0.03439 | H8: 0.03791 | I8: 0.03951 | J8: 0.04031 | K8: 0.04234
A9: Price | C9: 100.4688 | D9: 102.3594 | E9: 102.6719 | F9: 99.6562 | G9: 100.3594 | H9: 98.2344 | I9: 97.2812 | J9: 99.8125 | K9: 98.5938
A10: Units owned | C10: 9 | D10: 9 | E10: 9 | F10: 9 | G10: 9 | H10: 9 | I10: 9 | J10: 9 | K10: 9
A11: Owned Face Value | C11: 9000 | D11: 9000 | E11: 9000 | F11: 9000 | G11: 9000 | H11: 9000 | I11: 9000 | J11: 9000 | K11: 9000
A12: Owned Market Value | C12: 9042.192 | D12: =D11*D9/100 -> 9212.346 | E12: =E11*E9/100 -> 9240.471 | F12: =F11*F9/100 -> 8969.058 | G12: =G11*G9/100 -> 9032.346 | H12: =H11*H9/100 -> 8841.096 | I12: =I11*I9/100 -> 8755.308 | J12: =J11*J9/100 -> 8983.125 | K12: =K11*K9/100 -> 8873.442
A13: Leftover Cash | C13: =10000-C12 -> 957.808 | D13: =C13 -> 957.808 | E13: =D13 -> 957.808 | F13: =E13 -> 957.808 | G13: =F13 -> 957.808 | H13: =G13 -> 957.808 | I13: =H13 -> 957.808 | J13: =I13 -> 957.808 | K13: =J13 -> 957.808
A15: Time recorded | C15: 8:24 PM EST, Wednesday | D15: 5:05 PM EST, Thursday | E15: 5:05 PM EST, Thursday | F15: 5:05 PM EST, Thursday | G15: 6:47 PM EST, Thursday | H15: 8:20 PM EST, Thursday | I15: 2:10 PM EST, Friday | J15: 6:39 PM EST, Thursday | K15: 6:02 PM EST, Thursday
A17: Weekly profit/looss | D17: =(D9-C9)*D10 -> 17.0154 | E17: =(E9-D9)*E10 -> 2.8125 | F17: =(F9-E9)*F10 -> -27.1413 | G17: =(G9-F9)*G10 -> 6.3288 | H17: =(H9-G9)*H10 -> -19.125 | I17: =(I9-H9)*I10 -> -8.5788 | J17: =(J9-I9)*J10 -> 22.7817 | K17: =(K9-J9)*K10 -> -10.9683
A18: Cummulative Profit loss | D18: =(D9-$C9)*D10 -> 17.0154 | E18: =(E9-$C9)*E10 -> 19.8279 | F18: =(F9-$C9)*F10 -> -7.3134 | G18: =(G9-$C9)*G10 -> -0.9846 | H18: =(H9-$C9)*H10 -> -20.1096 | I18: =(I9-$C9)*I10 -> -28.6884 | J18: =(J9-$C9)*J10 -> -5.9067 | K18: =(K9-$C9)*K10 -> -16.875
A22: YOUR CHOICE | C22: I picked this bond because it's a Treasury bond of the US government with basically zero default risk and because it has a decent 3.56% yield with a slight discount. I also know that Treasury securities are very liquid and can be sold anytime before maturity.
A24: Bond | C24: 3-Year Treasury Note
A25: Face Value | C25: 10000
A26: Coupon Rate | C26: 0.035
A27: Maturity | C27: 47133
A28: Source | C28: https://www.treasurydirect.gov/instit/annceresult/press/preanre/2026/R_20260112_2.pdf | J28: Link
C29: Week 1 | D29: Week 2 | E29: Week 3 | F29: Week 4 | G29: Week 5 | H29: Week 6 | I29: Week 7 | J29: Week 8 | K29: Week 9
A31: Yield | C31: 0.0356
A32: Price | C32: 99.69 | D32: 99.8 | E32: 99.55 | F32: 99.68 | G32: 99.84 | H32: 100.15 | I32: 100.107 | J32: 100.054 | K32: 99.84
A33: Units owned | C33: 10
A34: Owned Face Value | C34: 10000
A35: Owned Market Value | C35: 9969 | D35: 9980 | E35: 9950 | F35: =F32*100 -> 9968 | G35: =G32*100 -> 9984 | H35: =H32*100 -> 10015 | I35: =I32*100 -> 10010.7 | J35: =J32*100 -> 10005.4 | K35: =K32*100 -> 9984
A36: Leftover Cash | C36: 31
A38: Time recorded | C38: 1/12/2026 @ 12:05pm PST | D38: 1/20/2026 @ 12:05pm PST | E38: 1/26/2026 @ 10:20am PST | F38: 2/2/26 @ 10:32pm | G38: 2/9/26 @ 8:51am | H38: 2/17/26 @ 8:14am | I38: 2/24/26 @ 11:52am | J38: 3/2/26 @ 10:47pm | K38: 3/9/26 @ 5pm
A40: Weekly profit/looss | C40: 0 | D40: =D35-C35 -> 11 | E40: =E35-D35 -> -30 | F40: =F35-E35 -> 18 | G40: =G35-F35 -> 16 | H40: =H35-G35 -> 31 | I40: =I35-H35 -> -4.3 | J40: =J35-I35 -> -5.3 | K40: =K35-J35 -> -21.4
A41: Cummulative Profit loss | C41: 0 | D41: =D35-$C$35 -> 11 | E41: =E35-$C$35 -> -19 | F41: =F35-$C$35 -> -1 | G41: =G35-$C$35 -> 15 | H41: =H35-$C$35 -> 46 | I41: =I35-$C$35 -> 41.7 | J41: =J35-$C$35 -> 36.4 | K41: =K35-$C$35 -> 15

Sheet Week2
A1: Stock | C1: Delta Air Lines Inc (DAL)
A2: Number of Shares Purchased | D2: 250
A3: Source
D7: Week 1 | E7: Week 2 | F7: Week 3 | G7: Week 4 | H7: Week 5 | I7: Week 6 | J7: Week 7 | K7: Week 8 | L7: Week 9
A8: Week 2 | B8: Price | E8: 39.84 | F8: 38.34 | G8: 39.19 | H8: 39.71 | I8: 38.91 | J8: 38.35 | K8: 37.55 | L8: 38.42
B10: Owned Market Value | E10: =E8*$D2 -> 9960 | F10: =F8*$D2 -> 9585 | G10: =G8*$D2 -> 9797.5 | H10: =H8*$D2 -> 9927.5 | I10: =I8*$D2 -> 9727.5 | J10: =J8*$D2 -> 9587.5 | K10: =K8*$D2 -> 9387.5 | L10: =L8*$D2 -> 9605
B11: Cash Leftover | D11: 10000 | E11: =D11-E10 -> 40 | F11: =E11 -> 40 | G11: =F11 -> 40 | H11: =G11 -> 40 | I11: =H11 -> 40 | J11: =I11 -> 40 | K11: =J11 -> 40 | L11: =K11 -> 40
A18: Weekly profit/looss | F18: =F10-E10 -> -375 | G18: =G10-F10 -> 212.5 | H18: =H10-G10 -> 130 | I18: =I10-H10 -> -200 | J18: =J10-I10 -> -140 | K18: =K10-J10 -> -200 | L18: =L10-K10 -> 217.5
A19: Cummulative Profit loss | F19: =F10-$E10 -> -375 | G19: =G10-$E10 -> -162.5 | H19: =H10-$E10 -> -32.5 | I19: =I10-$E10 -> -232.5 | J19: =J10-$E10 -> -372.5 | K19: =K10-$E10 -> -572.5 | L19: =L10-$E10 -> -355
A23: YOUR CHOICE | D23: Palantir is a short term high risk investment in many ways. First, it's known to be volatile with very strong momentum especially in the AI sector. In addition, Palantir's Q4 earnings are released on Feb 2 which can drive the stock up.
A25: Stock | D25: #VALUE!
A26: Number of Shares Purchased | D26: 59
A28: Source
E30: Week 2 | F30: Week 3 | G30: Week 4 | H30: Week 5 | I30: Week 6 | J30: Week 7 | K30: Week 8 | L30: Week 9
A31: Week 2 | B31: Price | E31: 168.58 | F31: 168.79 | G31: 149.59 | H31: 144.82 | I31: 133.88 | J31: 129.1 | K31: 145.21 | L31: 157.09
B33: Owned Market Value | E33: 9946.22 | F33: 9958.61 | G33: =G31*D26 -> 8825.81 | H33: =H31*$D$26 -> 8544.38 | I33: =I31*$D$26 -> 7898.92 | J33: =J31*$D$26 -> 7616.9 | K33: =K31*$D$26 -> 8567.39 | L33: =L31*$D$26 -> 9268.31
B34: Cash Leftover | D34: 10000 | E34: 53.78 | F34: 53.78 | G34: =F34 -> 53.78 | H34: =G34 -> 53.78 | I34: =H34 -> 53.78 | J34: =I34 -> 53.78 | K34: =J34 -> 53.78 | L34: =K34 -> 53.78
A39: Time recorded | E39: 1/20/26 @ 12:31pm | F39: 1/26/26 @ 10:17am | G39: 2/2/26 @ 10:37pm | H39: 2/9/26 @ 12:31pm | I39: 2/17/26 @ 2:02pm | J39: 2/24/26 @ 11:53am | K39: 3/2/24 @ 10:49pm | L39: 3/9/24 @ 3:30pm
A41: Weekly profit/looss | F41: =F33-E33 -> 12.39 | G41: =G33-F33 -> -1132.8 | H41: =H33-G33 -> -281.43 | I41: =I33-H33 -> -645.46 | J41: =J33-I33 -> -282.02 | K41: =K33-J33 -> 950.49 | L41: =L33-K33 -> 700.92
A42: Cummulative Profit loss | F42: =F33-$E$33 -> 12.39 | G42: =G33-$E$33 -> -1120.41 | H42: =H33-$E$33 -> -1401.84 | I42: =I33-$E$33 -> -2047.3 | J42: =J33-$E$33 -> -2329.32 | K42: =K33-$E$33 -> -1378.83 | L42: =L33-$E$33 -> -677.91

Sheet Week3
A1: Stock 1 | B1: Bank of America Corp (BAC) | E1: Number of Shares Purchased | F1: 150
A2: Stock 2 | B2: Honda Motor Co Ltd (HMC) | E2: Number of Shares Purchased | F2: 180
A3: Stock 3
A4: Stock 4
A5: Stock 5
A7: Source
D8: Week 1 | E8: Week 2 | F8: Week 3 | G8: Week 4 | H8: Week 5 | I8: Week 6 | J8: Week 7 | K8: Week 8 | L8: Week 9
A9: Stock 1 | B9: Price | F9: =34.25 -> 34.25 | G9: =35.3 -> 35.3 | H9: =36.04 -> 36.04 | I9: =35.61 -> 35.61 | J9: =35.12 -> 35.12 | K9: =34.2 -> 34.2 | L9: =33.43 -> 33.43
A10: Stock 2 | B10: Price | F10: 24.1 | G10: 24.27 | H10: 25.31 | I10: 24.4 | J10: 25.51 | K10: 25.89 | L10: 26.09
B12: Owned Market Value | F12: =F9*$F1+F10*$F2 -> 9475.5 | G12: =G9*$F1+G10*$F2 -> 9663.6 | H12: =H9*$F1+H10*$F2 -> 9961.8 | I12: =I9*$F1+I10*$F2 -> 9733.5 | J12: =J9*$F1+J10*$F2 -> 9859.8 | K12: =K9*$F1+K10*$F2 -> 9790.2 | L12: =L9*$F1+L10*$F2 -> 9710.7
B13: Cash Leftover | D13: 10000 | E13: =D13-E12 -> 10000 | F13: =E13-F12 -> 524.5 | G13: =F13 -> 524.5 | H13: =G13 -> 524.5 | I13: =H13 -> 524.5 | J13: =I13 -> 524.5 | K13: =J13 -> 524.5 | L13: =K13 -> 524.5
A20: Weekly profit/looss | G20: =G12-F12 -> 188.1 | H20: =H12-G12 -> 298.2 | I20: =I12-H12 -> -228.3 | J20: =J12-I12 -> 126.3 | K20: =K12-J12 -> -69.6 | L20: =L12-K12 -> -79.5
A21: Cummulative Profit loss | G21: =G12-$F12 -> 188.1 | H21: =H12-$F12 -> 486.3 | I21: =I12-$F12 -> 258 | J21: =J12-$F12 -> 384.3 | K21: =K12-$F12 -> 314.7 | L21: =L12-$F12 -> 235.2
A25: YOUR CHOICE NO SHORT SALES
A27: Stock 1 | B27: #VALUE! | F27: Desired Split | G27: 0.25 | I27: Num Shares | J27: 14 | L27: Value | M27: =J27*F35 -> 2618.28
A28: Stock 2 | B28: #VALUE! | F28: Desired Split | G28: 0.2 | I28: Num Shares | J28: 17 | L28: Value | M28: =J28*F36 -> 2220.88
A29: Stock 3 | B29: #VALUE! | F29: Desired Split | G29: 0.2 | I29: Num Shares | J29: 8 | L29: Value | M29: =J29*F37 -> 2019.92
A30: Stock 4 | B30: #VALUE! | F30: Desired Split | G30: 0.175 | I30: Num Shares | J30: 24 | L30: Value | M30: =J30*F38 -> 1815.6
A31: Stock 5 | B31: #VALUE! | F31: Desired Split | G31: 0.175 | I31: Num Shares | J31: 3 | L31: Value | M31: =J31*F39 -> 1315.71
C34: Live Price | E34: Week 2 | F34: Week 3 | G34: Week 4 | H34: Week 5 | I34: Week 6 | J34: Week 7 | K34: Week 8 | L34: Week 9
A35: Stock 1 | B35: Price | C35: {=_FV(B27,"Price")} -> 184.77 | F35: 187.02 | G35: {=_xlfn.STOCKHISTORY(B27, "2026-01-30", "2026-01-30", 0, 0, 1)} -> 191.13 | H35: {=_xlfn.STOCKHISTORY(B27, "2026-02-06", "2026-02-06", 0, 0, 1)} -> 185.41 | I35: {=_xlfn.STOCKHISTORY(B27, "2026-02-13", "2026-02-13", 0, 0, 1)} -> 182.81 | J35: {=_xlfn.STOCKHISTORY(B27, "2026-02-23", "2026-02-23", 0, 0, 1)} -> 191.55 | K35: 182.18 | L35: {=_xlfn.STOCKHISTORY(B27, "2026-03-09", "2026-03-09", 0, 0, 1)} -> 182.65
A36: Stock 2 | B36: Price | C36: {=_FV(B28,"Price")} -> 112.33 | F36: 130.64 | G36: {=_xlfn.STOCKHISTORY(B28, "2026-01-30", "2026-01-30", 0, 0, 1)} -> 125.28 | H36: {=_xlfn.STOCKHISTORY(B28, "2026-02-06", "2026-02-06", 0, 0, 1)} -> 111.4 | I36: {=_xlfn.STOCKHISTORY(B28, "2026-02-13", "2026-02-13", 0, 0, 1)} -> 121.44 | J36: {=_xlfn.STOCKHISTORY(B28, "2026-02-23", "2026-02-23", 0, 0, 1)} -> 124.05 | K36: 113.31 | L36: {=_xlfn.STOCKHISTORY(B28, "2026-03-09", "2026-03-09", 0, 0, 1)} -> 115.98
A37: Stock 3 | B37: Price | C37: {=_FV(B29,"Price")} -> 203.23 | F37: 252.49 | G37: {=_xlfn.STOCKHISTORY(B29, "2026-01-30", "2026-01-30", 0, 0, 1)} -> 236.73 | H37: {=_xlfn.STOCKHISTORY(B29, "2026-02-06", "2026-02-06", 0, 0, 1)} -> 208.44 | I37: {=_xlfn.STOCKHISTORY(B29, "2026-02-13", "2026-02-13", 0, 0, 1)} -> 207.32 | J37: {=_xlfn.STOCKHISTORY(B29, "2026-02-23", "2026-02-23", 0, 0, 1)} -> 196.6 | K37: 196.62 | L37: {=_xlfn.STOCKHISTORY(B29, "2026-03-09", "2026-03-09", 0, 0, 1)} -> 202.68
A38: Stock 4 | B38: Price | C38: {=_FV(B30,"Price")} -> 68.5 | F38: 75.65 | G38: {=_xlfn.STOCKHISTORY(B30, "2026-01-30", "2026-01-30", 0, 0, 1)} -> 74.88 | H38: {=_xlfn.STOCKHISTORY(B30, "2026-02-06", "2026-02-06", 0, 0, 1)} -> 74.59 | I38: {=_xlfn.STOCKHISTORY(B30, "2026-02-13", "2026-02-13", 0, 0, 1)} -> 74.75 | J38: {=_xlfn.STOCKHISTORY(B30, "2026-02-23", "2026-02-23", 0, 0, 1)} -> 71.54 | K38: 72.64 | L38: {=_xlfn.STOCKHISTORY(B30, "2026-03-09", "2026-03-09", 0, 0, 1)} -> 67.49
A39: Stock 5 | B39: Price | C39: {=_FV(B31,"Price")} -> 399.235 | F39: 438.57 | G39: {=_xlfn.STOCKHISTORY(B31, "2026-01-30", "2026-01-30", 0, 0, 1)} -> 430.41 | H39: {=_xlfn.STOCKHISTORY(B31, "2026-02-06", "2026-02-06", 0, 0, 1)} -> 411.11 | I39: {=_xlfn.STOCKHISTORY(B31, "2026-02-13", "2026-02-13", 0, 0, 1)} -> 417.44 | J39: {=_xlfn.STOCKHISTORY(B31, "2026-02-23", "2026-02-23", 0, 0, 1)} -> 399.83 | K39: 400.94 | L39: {=_xlfn.STOCKHISTORY(B31, "2026-03-09", "2026-03-09", 0, 0, 1)} -> 398.68
B41: Owned Market Value | F41: =$J$27*F35+$J$28*F36+$J$29*F37+$J$30*F38+$J$31*F39 -> 9990.39 | G41: =$J$27*G35+$J$28*G36+$J$29*G37+$J$30*G38+$J$31*G39 -> 9787.77 | H41: =$J$27*H35+$J$28*H36+$J$29*H37+$J$30*H38+$J$31*H39 -> 9180.55 | I41: =$J$27*I35+$J$28*I36+$J$29*I37+$J$30*I38+$J$31*I39 -> 9328.7 | J41: =$J$27*J35+$J$28*J36+$J$29*J37+$J$30*J38+$J$31*J39 -> 9279.8 | K41: =$J$27*K35+$J$28*K36+$J$29*K37+$J$30*K38+$J$31*K39 -> 8995.93 | L41: =$J$27*L35+$J$28*L36+$J$29*L37+$J$30*L38+$J$31*L39 -> 8966
B42: Cash Leftover | F42: =10000-F41 -> 9.61 | G42: =F42 -> 9.61 | H42: =G42 -> 9.61 | I42: =H42 -> 9.61 | J42: =I42 -> 9.61 | K42: =J42 -> 9.61 | L42: =K42 -> 9.61
A46: Weekly profit/looss | G46: =G41-F41 -> -202.62 | H46: =H41-G41 -> -607.22 | I46: =I41-H41 -> 148.15 | J46: =J41-I41 -> -48.9 | K46: =K41-J41 -> -283.87 | L46: =L41-K41 -> -29.93
A47: Cummulative Profit loss | G47: =G41-$F$41 -> -202.62 | H47: =H41-$F$41 -> -809.84 | I47: =I41-$F$41 -> -661.69 | J47: =J41-$F$41 -> -710.59 | K47: =K41-$F$41 -> -994.46 | L47: =L41-$F$41 -> -1024.39

Sheet Week4
A1: Short Stock | C1: Nokia Corp (NOK) | F1: Long Stock | G1: United Airlines Holdings Inc (UAL)
A2: Shares sold | C2: 8500 | F2: Shares purchased | G2: 1000
A3: Source
D4: Week 1 | E4: Week 2 | F4: Week 3 | G4: Week 4 | H4: Week 5 | I4: Week 6 | J4: Week 7 | K4: Week 8 | L4: Week 9
A5: Stock 1 | B5: Price | C5: short | G5: =4.8 -> 4.8 | H5: 4.9 | I5: 4.65 | J5: 4.76 | K5: 4.66 | L5: 4.67
A6: Stock 2 | B6: Price | G6: =49.19 -> 49.19 | H6: 51.81 | I6: 49.78 | J6: 49.58 | K6: 50.68 | L6: 52.5
B8: Owned Market Value | G8: =-$C2*G5+$G2*G6 -> 8390 | H8: =-$C2*H5+$G2*H6 -> 10160 | I8: =-$C2*I5+$G2*I6 -> 10255 | J8: =-$C2*J5+$G2*J6 -> 9120 | K8: =-$C2*K5+$G2*K6 -> 11070 | L8: =-$C2*L5+$G2*L6 -> 12805
B9: Cash Leftover | F9: 10000 | G9: =F9-G8 -> 1610 | H9: =G9 -> 1610 | I9: =H9 -> 1610 | J9: =I9 -> 1610 | K9: =J9 -> 1610 | L9: =K9 -> 1610
A16: Weekly profit/looss | H16: =H8-G8 -> 1770 | I16: =I8-H8 -> 95 | J16: =J8-I8 -> -1135 | K16: =K8-J8 -> 1950 | L16: =L8-K8 -> 1735
A17: Cummulative Profit loss | H17: =H8-$G8 -> 1770 | I17: =I8-$G8 -> 1865 | J17: =J8-$G8 -> 730 | K17: =K8-$G8 -> 2680 | L17: =L8-$G8 -> 4415
A20: YOUR CHOICE | C20: You must go short on at least one stock and long in at least up to three stocks, your net portfolio is still $10,000 (or less)
A22: Short Stock | B22: #VALUE! | I22: Num Shares | J22: 151 | L22: Value | M22: =$J$22*(2*$G$30-C30) -> 1349.94
A23: Long Stock 1 | B23: #VALUE! | I23: Num Shares | J23: 15 | L23: Value | M23: =J23*C31 -> 3214.95
A24: Long Stock 2 | B24: #VALUE! | I24: Num Shares | J24: 9 | L24: Value | M24: =J24*C32 -> 2763.36
A25: Long Stock 3 | B25: #VALUE! | I25: Num Shares | J25: 7 | L25: Value | M25: =J25*C33 -> 2397.64
C29: Live Price | E29: Week 2 | F29: Week 3 | G29: Week 4 | H29: Week 5 | I29: Week 6 | J29: Week 7 | K29: Week 8 | L29: Week 9
A30: Stock 1 | B30: Price | C30: {=_FV(B22,"Price")} -> 4.92 | G30: {=_xlfn.STOCKHISTORY(B22, "2026-01-30", "2026-01-30", 0, 0, 1)} -> 6.93 | H30: {=_xlfn.STOCKHISTORY(B22, "2026-02-06", "2026-02-06", 0, 0, 1)} -> 5.22 | I30: {=_xlfn.STOCKHISTORY(B22, "2026-02-13", "2026-02-13", 0, 0, 1)} -> 4.83 | J30: {=_xlfn.STOCKHISTORY(B22, "2026-02-23", "2026-02-23", 0, 0, 1)} -> 4.93 | K30: {=_xlfn.STOCKHISTORY(B22, "2026-02-27", "2026-02-27", 0, 0, 1)} -> 5.21 | L30: {=_xlfn.STOCKHISTORY(B22, "2026-03-06", "2026-03-06", 0, 0, 4)} -> 5.07
A31: Stock 2 | B31: Price | C31: {=_FV(B23,"Price")} -> 214.33 | G31: {=_xlfn.STOCKHISTORY(B23, "2026-01-30", "2026-01-30", 0, 0, 1)} -> 239.3 | H31: {=_xlfn.STOCKHISTORY(B23, "2026-02-06", "2026-02-06", 0, 0, 1)} -> 210.32 | I31: {=_xlfn.STOCKHISTORY(B23, "2026-02-13", "2026-02-13", 0, 0, 1)} -> 198.79 | J31: {=_xlfn.STOCKHISTORY(B23, "2026-02-23", "2026-02-23", 0, 0, 1)} -> 205.27 | K31: {=_xlfn.STOCKHISTORY(B23, "2026-02-27", "2026-02-27", 0, 0, 1)} -> 210 | L31: {=_xlfn.STOCKHISTORY(B23, "2026-03-06", "2026-03-06", 0, 0, 3)} -> 217.32
A32: Stock 3 | B32: Price | C32: {=_FV(B24,"Price")} -> 307.04 | G32: {=_xlfn.STOCKHISTORY(B24, "2026-01-30", "2026-01-30", 0, 0, 1)} -> 338 | H32: {=_xlfn.STOCKHISTORY(B24, "2026-02-06", "2026-02-06", 0, 0, 1)} -> 322.86 | I32: {=_xlfn.STOCKHISTORY(B24, "2026-02-13", "2026-02-13", 0, 0, 1)} -> 305.72 | J32: {=_xlfn.STOCKHISTORY(B24, "2026-02-23", "2026-02-23", 0, 0, 1)} -> 311.49 | K32: {=_xlfn.STOCKHISTORY(B24, "2026-02-27", "2026-02-27", 0, 0, 1)} -> 311.76 | L32: {=_xlfn.STOCKHISTORY(B24, "2026-03-06", "2026-03-06", 0, 0, 3)} -> 300.53
A33: Stock 4 | B33: Price | C33: {=_FV(B25,"Price")} -> 342.52 | G33: {=_xlfn.STOCKHISTORY(B25, "2026-01-30", "2026-01-30", 0, 0, 1)} -> 331.3 | H33: {=_xlfn.STOCKHISTORY(B25, "2026-02-06", "2026-02-06", 0, 0, 1)} -> 332.92 | I33: {=_xlfn.STOCKHISTORY(B25, "2026-02-13", "2026-02-13", 0, 0, 1)} -> 325.17 | J33: {=_xlfn.STOCKHISTORY(B25, "2026-02-23", "2026-02-23", 0, 0, 1)} -> 330.34 | K33: {=_xlfn.STOCKHISTORY(B25, "2026-02-27", "2026-02-27", 0, 0, 1)} -> 319.55 | L33: {=_xlfn.STOCKHISTORY(B25, "2026-03-06", "2026-03-06", 0, 0, 3)} -> 343.51
B36: Owned Market Value | G36: =$J$22*G30+$J$23*G31+$J$24*G32+$J$25*G33 -> 9997.03 | H36: =$J$22*(2*$G$30-H30)+$J$23*H31+$J$24*H32+$J$25*H33 -> 9695.62 | I36: =$J$22*I30+$J$23*I31+$J$24*I32+$J$25*I33 -> 8738.85 | J36: =$J$22*J30+$J$23*J31+$J$24*J32+$J$25*J33 -> 8939.27 | K36: =$J$22*K30+$J$23*K31+$J$24*K32+$J$25*K33 -> 8979.4 | L36: =$J$22*L30+$J$23*L31+$J$24*L32+$J$25*L33 -> 9134.71
B37: Cash Leftover | G37: =10000-G36 -> 2.97 | H37: =G37 -> 2.97 | I37: =H37 -> 2.97 | J37: =I37 -> 2.97 | K37: =J37 -> 2.97 | L37: =K37 -> 2.97
A41: Weekly profit/looss | H41: =H36-G36 -> -301.41 | I41: =I36-H36 -> -956.77 | J41: =J36-I36 -> 200.42 | K41: =K36-J36 -> 40.13 | L41: =L36-K36 -> 155.31
A42: Cummulative Profit loss | H42: =H36-$G$36 -> -301.41 | I42: =I36-$G$36 -> -1258.18 | J42: =J36-$G$36 -> -1057.76 | K42: =K36-$G$36 -> -1017.63 | L42: =L36-$G$36 -> -862.32

Sheet Week5
A1: Unlimited Liability
A2: Equity and debt | B2: 3 | C2: Fed Interest Rate | E2: 0.0458
C3: Weekly Interest Rate | E3: =E2/52 -> 0.00088076923
A5: Stock 1 | B5: Walt Disney Co. (DIS) | E5: Number of Shares Purchased | F5: 55
A6: Stock 2 | B6: Sony Group Corp (SONY) | E6: Number of Shares Purchased | F6: 70
A7: Stock 3 | B7: Hershey Co. (HSY) | E7: Number of Shares Purchased | F7: 10
A8: Stock 4
A9: Stock 5
A10: Borrowed Money | C10: =H17-10000 -> 3876.55
D12: Week 1 | E12: Week 2 | F12: Week 3 | G12: Week 4 | H12: Week 5 | I12: Week 6 | J12: Week 7 | K12: Week 8 | L12: Week 9
A13: Stock 1 | H13: 103.21 | I13: 108 | J13: 107.44 | K13: 104.54 | L13: 105.9
A14: Stock 2 | H14: 83.8 | I14: 91.5 | J14: 86.7 | K14: 86.68 | L14: 87.34
A15: Stock 3 | H15: 233.4 | I15: 235.3 | J15: 238.3 | K15: 240.47 | L15: 238.4
A17: Portfolio value | H17: =SUMPRODUCT($F5:$F7,H13:H15) -> 13876.55 | I17: =SUMPRODUCT($F5:$F7,I13:I15) -> 14698 | J17: =SUMPRODUCT($F5:$F7,J13:J15) -> 14361.2 | K17: =SUMPRODUCT($F5:$F7,K13:K15) -> 14222 | L17: =SUMPRODUCT($F5:$F7,L13:L15) -> 14322.3
A18: interest | I18: =(C10+H18)*E3 -> 3.414346 | J18: =($C10+SUM($H18:I18))*$E3 -> 3.4173532 | K18: =($C10+SUM($H18:J18))*$E3 -> 3.4203631 | L18: =($C10+SUM($H18:K18))*$E3 -> 3.4233757
A19: Liquidation value | H19: =H17-$C10-H18 -> 10000 | I19: =I17-$C10-I18 -> 10818.036 | J19: =J17-$C10-SUM($H18:J18) -> 10477.818 | K19: =K17-$C10-SUM($H18:K18) -> 10335.198 | L19: =L17-$C10-SUM($H18:L18) -> 10432.075
A21: Weekly profit/looss | I21: =I17-H17-H18 -> 821.45 | J21: =J17-I17-I18 -> -340.21435 | K21: =K17-J17-J18 -> -142.61735 | L21: =L17-K17-K18 -> 96.879637
A22: Cummulative Profit loss | I22: =(I17-$H17)-I18 -> 818.03565 | J22: =(J17-$H17)-J18 -> 481.23265 | K22: =(K17-$H17)-K18 -> 342.02964 | L22: =(L17-$H17)-L18 -> 442.32662
A25: Your choice
A27: Equity and debt | C27: Fed Interest Rate | E27: 0.0364
C28: Weekly Interest Rate | E28: =E27/52 -> 0.0007
A30: Stock 1 | B30: #VALUE! | G30: Num Shares | H30: 48 | J30: Value | K30: =H30*C38 -> 8899.68
A31: Stock 2 | B31: #VALUE! | G31: Num Shares | H31: 78 | J31: Value | K31: =H31*C39 -> 6459.96
A32: Stock 3 | B32: #VALUE! | G32: Num Shares | H32: 52 | J32: Value | K32: =H32*C40 -> 5908.76
A33: Stock 4 | B33: #VALUE! | G33: Num Shares | H33: 12 | J33: Value | K33: =H33*C41 -> 4746
A34: Stock 5 | B34: #VALUE! | G34: Num Shares | H34: 24 | J34: Value | K34: =H34*C42 -> 3962.88
A35: Borrowed Money | C35: =H44-10000 -> 19977.28
C37: Live Price | D37: Week 1 | E37: Week 2 | F37: Week 3 | G37: Week 4 | H37: Week 5 | I37: Week 6 | J37: Week 7 | K37: Week 8 | L37: Week 9
A38: Stock 1 | C38: 185.41 | H38: {=_xlfn.STOCKHISTORY(B30, "2026-02-06", "2026-02-06", 0, 0, 1)} -> 185.41 | I38: {=_xlfn.STOCKHISTORY(B30, "2026-02-13", "2026-02-13", 0, 0, 1)} -> 182.81 | J38: {=_xlfn.STOCKHISTORY(B30, "2026-02-23", "2026-02-23", 0, 0, 1)} -> 191.55 | K38: {=_xlfn.STOCKHISTORY(B30, "2026-02-27", "2026-02-27", 0, 0, 1)} -> 177.19 | L38: {=_xlfn.STOCKHISTORY(B30, "2026-03-09", "2026-03-09", 0, 0, 3)} -> 182.91
A39: Stock 2 | C39: 82.82 | H39: {=_xlfn.STOCKHISTORY(B31, "2026-02-06", "2026-02-06", 0, 0, 1)} -> 82.82 | I39: {=_xlfn.STOCKHISTORY(B31, "2026-02-13", "2026-02-13", 0, 0, 1)} -> 75.97 | J39: {=_xlfn.STOCKHISTORY(B31, "2026-02-23", "2026-02-23", 0, 0, 1)} -> 71.78 | K39: {=_xlfn.STOCKHISTORY(B31, "2026-02-27", "2026-02-27", 0, 0, 1)} -> 75.85 | L39: {=_xlfn.STOCKHISTORY(B31, "2026-03-09", "2026-03-09", 0, 0, 3)} -> 79.65
A40: Stock 3 | C40: 113.63 | H40: {=_xlfn.STOCKHISTORY(B32, "2026-02-06", "2026-02-06", 0, 0, 1)} -> 113.63 | I40: {=_xlfn.STOCKHISTORY(B32, "2026-02-13", "2026-02-13", 0, 0, 1)} -> 112.9 | J40: {=_xlfn.STOCKHISTORY(B32, "2026-02-23", "2026-02-23", 0, 0, 1)} -> 118.75 | K40: {=_xlfn.STOCKHISTORY(B32, "2026-02-27", "2026-02-27", 0, 0, 1)} -> 118.4 | L40: {=_xlfn.STOCKHISTORY(B32, "2026-03-09", "2026-03-09", 0, 0, 3)} -> 116.41
A41: Stock 4 | C41: 395.5 | H41: {=_xlfn.STOCKHISTORY(B33, "2026-02-06", "2026-02-06", 0, 0, 1)} -> 395.5 | I41: {=_xlfn.STOCKHISTORY(B33, "2026-02-13", "2026-02-13", 0, 0, 1)} -> 429.64 | J41: {=_xlfn.STOCKHISTORY(B33, "2026-02-23", "2026-02-23", 0, 0, 1)} -> 350.33 | K41: {=_xlfn.STOCKHISTORY(B33, "2026-02-27", "2026-02-27", 0, 0, 1)} -> 371.98 | L41: {=_xlfn.STOCKHISTORY(B33, "2026-03-09", "2026-03-09", 0, 0, 3)} -> 438.28
A42: Stock 5 | C42: 165.12 | H42: {=_xlfn.STOCKHISTORY(B34, "2026-02-06", "2026-02-06", 0, 0, 1)} -> 165.12 | I42: {=_xlfn.STOCKHISTORY(B34, "2026-02-13", "2026-02-13", 0, 0, 1)} -> 164.32 | J42: {=_xlfn.STOCKHISTORY(B34, "2026-02-23", "2026-02-23", 0, 0, 1)} -> 160.24 | K42: {=_xlfn.STOCKHISTORY(B34, "2026-02-27", "2026-02-27", 0, 0, 1)} -> 175.85 | L42: {=_xlfn.STOCKHISTORY(B34, "2026-03-09", "2026-03-09", 0, 0, 3)} -> 203.49
A44: Portfolio value | H44: =SUMPRODUCT(H38:H42,$H$30:$H$34) -> 29977.28 | I44: =SUMPRODUCT(I38:I42,$H$30:$H$34) -> 29670.7 | J44: =SUMPRODUCT(J38:J42,$H$30:$H$34) -> 29017.96 | K44: =SUMPRODUCT(K38:K42,$H$30:$H$34) -> 29262.38 | L44: =SUMPRODUCT(L38:L42,$H$30:$H$34) -> 31188.82
A45: interest | I45: =($C$35+H45)*$E$28 -> 13.984096 | J45: =($C$35+I45)*$E$28 -> 13.993885 | K45: =($C$35+J45)*$E$28 -> 13.993892 | L45: =($C$35+K45)*$E$28 -> 13.993892
A46: Liquidation value | H46: =H44-C35 -> 10000 | I46: =I44-$C$35-I45 -> 9679.4359 | J46: =J44-$C$35-J45 -> 9026.6861 | K46: =K44-$C$35-K45 -> 9271.1061 | L46: =L44-$C$35-L45 -> 11197.546
A48: Weekly profit/looss | I48: =I44-H44 -> -306.58 | J48: =J44-I44 -> -652.74 | K48: =K44-J44 -> 244.42 | L48: =L44-K44 -> 1926.44
A49: Cummulative Profit loss | I49: =I44-$H$44 -> -306.58 | J49: =J44-$H$44 -> -959.32 | K49: =K44-$H$44 -> -714.9 | L49: =L44-$H$44 -> 1211.54

Sheet Week6
A1: Limited liability
A2: Equity and debt | C2: Fed Interest Rate | E2: 0.0458
C3: Weekly Interest Rate | E3: =E2/52 -> 0.00088076923
A5: Stock 1 | B5: NVIDIA Corp (NVDA) | E5: Number of Shares Purchased | F5: 40
A6: Stock 2 | B6: Johnson & Johnson (JNJ) | E6: Number of Shares Purchased | F6: 50
A7: Stock 3 | B7: Target Corp (TGT) | E7: Number of Shares Purchased | F7: 40
A8: Stock 4
A9: Stock 5
A10: Borrowed Money | C10: =I17-10000 -> 13963.2
D12: Week 1 | E12: Week 2 | F12: Week 3 | G12: Week 4 | H12: Week 5 | I12: Week 6 | J12: Week 7 | K12: Week 8 | L12: Week 9
A13: Stock 1 | I13: 223.33 | J13: 211.4 | K13: 236.37 | L13: 232.38
A14: Stock 2 | I14: 164.36 | J14: 159.44 | K14: 157.41 | L14: 152.25
A15: Stock 3 | I15: 170.3 | J15: 171.68 | K15: 165.5 | L15: 165.5
A17: Portfolio value | I17: =SUMPRODUCT($F5:$F7,I13:I15) -> 23963.2 | J17: =SUMPRODUCT($F5:$F7,J13:J15) -> 23295.2 | K17: =SUMPRODUCT($F5:$F7,K13:K15) -> 23945.3 | L17: =SUMPRODUCT($F5:$F7,L13:L15) -> 23527.7
A18: interest | J18: =($C10+SUM($H18:I18))*$E3 -> 12.298357 | K18: =($C10+SUM($H18:J18))*$E3 -> 12.309189 | L18: =($C10+SUM($H18:K18))*$E3 -> 12.32003
A19: Liquidation value | I19: =I17-$C10-I18 -> 10000 | J19: =J17-$C10-SUM($H18:J18) -> 9319.7016 | K19: =K17-$C10-SUM($H18:K18) -> 9957.4925 | L19: =L17-$C10-SUM($H18:L18) -> 9527.5724
A21: Weekly profit/looss | J21: =J17-I17-I18 -> -668 | K21: =K17-J17-J18 -> 637.80164 | L21: =L17-K17-K18 -> -429.90919
A22: Cummulative Profit loss | J22: =(J17-$I17)-J18 -> -680.29836 | K22: =(K17-$I17)-K18 -> -30.209189 | L22: =(L17-$I17)-L18 -> -447.82003
A24: Return
A26: Equity and debt | C26: Fed Interest Rate | E26: 0.0364
C27: Weekly Interest Rate | E27: =E26/52 -> 0.0007
A29: Stock 1 | B29: #VALUE! | F29: Num Shares | G29: 40 | I29: Value | J29: =G29*C37 -> 7084 | L29: Portion | M29: =J29/$J$34 -> 0.23629039
A30: Stock 2 | B30: #VALUE! | F30: Num Shares | G30: 62 | I30: Value | J30: =G30*C38 -> 7977.54 | L30: Portion | M30: =J30/$J$34 -> 0.26609486
A31: Stock 3 | B31: #VALUE! | F31: Num Shares | G31: 208 | I31: Value | J31: =G31*C39 -> 6262.88 | L31: Portion | M31: =J31/$J$34 -> 0.20890152
A32: Stock 4 | B32: #VALUE! | F32: Num Shares | G32: 27 | I32: Value | J32: =G32*C40 -> 4975.83 | L32: Portion | M32: =J32/$J$34 -> 0.16597132
A33: Stock 5 | B33: #VALUE! | F33: Num Shares | G33: 29 | I33: Value | J33: =G33*C41 -> 3679.81 | L33: Portion | M33: =J33/$J$34 -> 0.12274192
A34: Borrowed Money | C34: =I43-10000 -> 19980.06 | I34: Total | J34: =SUM(J29:J33) -> 29980.06 | L34: Total | M34: =J34/$J$34 -> 1
C36: Live Price | D36: Week 1 | E36: Week 2 | F36: Week 3 | G36: Week 4 | H36: Week 5 | I36: Week 6 | J36: Week 7 | K36: Week 8 | L36: Week 9
A37: Stock 1 | C37: 177.1 | I37: {=_xlfn.STOCKHISTORY(B29, "2026-02-17", "2026-02-17", 0, 0, 1)} -> 177.1 | J37: {=_xlfn.STOCKHISTORY(B29, "2026-02-23", "2026-02-23", 0, 0, 1)} -> 157.6 | K37: {=_xlfn.STOCKHISTORY(B29, "2026-02-27", "2026-02-27", 0, 0, 1)} -> 168.41 | L37: {=_xlfn.STOCKHISTORY(B29, "2026-03-09", "2026-03-09", 0, 0, 3)} -> 183.105
A38: Stock 2 | C38: 128.67 | I38: {=_xlfn.STOCKHISTORY(B30, "2026-02-17", "2026-02-17", 0, 0, 1)} -> 128.67 | J38: {=_xlfn.STOCKHISTORY(B30, "2026-02-23", "2026-02-23", 0, 0, 1)} -> 123.71 | K38: {=_xlfn.STOCKHISTORY(B30, "2026-02-27", "2026-02-27", 0, 0, 1)} -> 129.5 | L38: {=_xlfn.STOCKHISTORY(B30, "2026-03-09", "2026-03-09", 0, 0, 3)} -> 140.19
A39: Stock 3 | C39: 30.11 | I39: {=_xlfn.STOCKHISTORY(B31, "2026-02-17", "2026-02-17", 0, 0, 1)} -> 30.11 | J39: {=_xlfn.STOCKHISTORY(B31, "2026-02-23", "2026-02-23", 0, 0, 1)} -> 30.71 | K39: {=_xlfn.STOCKHISTORY(B31, "2026-02-27", "2026-02-27", 0, 0, 1)} -> 32.39 | L39: {=_xlfn.STOCKHISTORY(B31, "2026-03-09", "2026-03-09", 0, 0, 3)} -> 32.16
A40: Stock 4 | C40: 184.29 | I40: {=_xlfn.STOCKHISTORY(B32, "2026-02-17", "2026-02-17", 0, 0, 1)} -> 184.29 | J40: {=_xlfn.STOCKHISTORY(B32, "2026-02-23", "2026-02-23", 0, 0, 1)} -> 178.16 | K40: {=_xlfn.STOCKHISTORY(B32, "2026-02-27", "2026-02-27", 0, 0, 1)} -> 194.79 | L40: {=_xlfn.STOCKHISTORY(B32, "2026-03-09", "2026-03-09", 0, 0, 3)} -> 203.67
A41: Stock 5 | C41: 126.89 | I41: {=_xlfn.STOCKHISTORY(B33, "2026-02-17", "2026-02-17", 0, 0, 1)} -> 126.89 | J41: {=_xlfn.STOCKHISTORY(B33, "2026-02-23", "2026-02-23", 0, 0, 1)} -> 123.78 | K41: {=_xlfn.STOCKHISTORY(B33, "2026-02-27", "2026-02-27", 0, 0, 1)} -> 127.45 | L41: {=_xlfn.STOCKHISTORY(B33, "2026-03-09", "2026-03-09", 0, 0, 3)} -> 118.14
A43: Portfolio value | I43: =SUMPRODUCT(I37:I41,$G$29:$G$33) -> 29980.06 | J43: =SUMPRODUCT(J37:J41,$G$29:$G$33) -> 28761.64 | K43: =SUMPRODUCT(K37:K41,$G$29:$G$33) -> 30457.9 | L43: =SUMPRODUCT(L37:L41,$G$29:$G$33) -> 31630.41
A44: interest | I44: =($C$35+H44)*$E$28 -> 0 | J44: =($C$34+I44)*$E$27 -> 13.986042 | K44: =($C$34+J44)*$E$27 -> 13.995832 | L44: =($C$34+K44)*$E$27 -> 13.995839
A45: Liquidation value | I45: =I43-$C$34-SUM(F44:I44) -> 10000 | J45: =J43-$C$34-SUM(G44:J44) -> 8767.594 | K45: =K43-$C$34-SUM(H44:K44) -> 10449.858 | L45: =L43-$C$34-SUM(I44:L44) -> 11608.372
A47: Weekly profit/looss | J47: =J43-I43 -> -1218.42 | K47: =K43-J43 -> 1696.26 | L47: =L43-K43 -> 1172.51
A48: Cummulative Profit loss | J48: =J43-$I$43 -> -1218.42 | K48: =K43-$I$43 -> 477.84 | L48: =L43-$I$43 -> 1650.35

Sheet Week7
A1: Commodity | D1: Platinum
A2: Units purchased | D2: 9
A3: Source
D7: Week 1 | E7: Week 2 | F7: Week 3 | G7: Week 4 | H7: Week 5 | I7: Week 6 | J7: Week 7 | K7: Week 8 | L7: Week 9
A8: Week 2 | B8: Price | J8: 925.1 | K8: 947.5 | L8: 964.9
B10: Owned Market Value | J10: =J8*$D2 -> 8325.9 | K10: =K8*$D2 -> 8527.5 | L10: =L8*$D2 -> 8684.1
B11: Cash Leftover | I11: 10000 | J11: =I11-J10 -> 1674.1 | K11: =J11 -> 1674.1 | L11: =K11 -> 1674.1
A18: Weekly profit/looss | K18: =K10-J10 -> 201.6 | L18: =L10-K10 -> 156.6
A19: Cummulative Profit loss | K19: =K10-$J10 -> 201.6 | L19: =L10-$J10 -> 358.2
A22: Your Choice
A24: Capital | C24: 10000
A25: Commodity | C25: #VALUE!
A26: Units purchased | C26: =_xlfn.FLOOR.MATH(C24/J32) -> 127
A27: Source | C27: https://www.google.com/finance/beta/quote/SIW00:COMEX?sa=X&ved=2ahUKEwjMjrTMk_OSAxVWIUQIHdtlPUoQ3ecFegQIIxAT
D31: Week 1 | E31: Week 2 | F31: Week 3 | G31: Week 4 | H31: Week 5 | I31: Week 6 | J31: Week 7 | K31: Week 8 | L31: Week 9
A32: Week 2 | B32: Price | J32: 78.39 | K32: 90.38 | L32: {=_xlfn.STOCKHISTORY(C25, "2026-03-09", "2026-03-09", 0, 0, 3)} -> 87.405
B34: Owned Market Value | J34: =J32*$C$26 -> 9955.53 | K34: =K32*$C$26 -> 11478.26 | L34: =L32*$C$26 -> 11100.435
B35: Cash Leftover | J35: =$C$24-$J$32*$C$26 -> 44.47 | K35: =$C$24-$J$32*$C$26 -> 44.47 | L35: =$C$24-$J$32*$C$26 -> 44.47
A37: Weekly profit/looss | K37: =K34-J34 -> 1522.73 | L37: =L34-K34 -> -377.825
A38: Cummulative Profit loss | K38: =K34-$J$34 -> 1522.73 | L38: =L34-$J$34 -> 1144.905

Sheet Week8
A1: Week 9 | B1: Mutual fund | D1: Vanguard Total Stock Market Index Fund Investor Shares (VTSMX)
A2: Shares Owned | D2: 100
A3: Source
D7: Week 1 | E7: Week 2 | F7: Week 3 | G7: Week 4 | H7: Week 5 | I7: Week 6 | J7: Week 7 | K7: Week 8 | L7: Week 9
A8: Week 2 | B8: Price | K8: 98.14 | L8: 97.48
B10: Owned Market Value | K10: =K8*$D2 -> 9814 | L10: =L8*$D2 -> 9748
B11: Cash Leftover | J11: 10000 | K11: =J11-K10 -> 186 | L11: =K11 -> 186
A18: Weekly profit/looss | K18: =K10-J10 -> 9814 | L18: =L10-K10 -> -66
A19: Cummulative Profit loss | K19: =K10-$J10 -> 9814 | L19: =L10-$J10 -> 9748
A22: your choice
A23: Week 9 | B23: Mutual fund | D23: #VALUE!
A24: Shares Owned | D24: =_xlfn.FLOOR.MATH(F24/K30) -> 179 | F24: 10000
A25: Source
D29: Week 1 | E29: Week 2 | F29: Week 3 | G29: Week 4 | H29: Week 5 | I29: Week 6 | J29: Week 7 | K29: Week 8 | L29: Week 9
A30: Week 2 | B30: Price | K30: {=_xlfn.STOCKHISTORY($D$23, "2026-02-27", "2026-02-27", 0, 0, 1)} -> 55.67 | L30: {=_xlfn.STOCKHISTORY($D$23, "2026-03-09", "2026-03-09", 0, 0, 1)} -> 56.24
B32: Owned Market Value | K32: =K30*$D$24 -> 9964.93 | L32: =L30*$D$24 -> 10066.96
B33: Cash Leftover | K33: =$F$24-$K$32 -> 35.07 | L33: =$F$24-$K$32 -> 35.07
A35: Weekly profit/looss | L35: =L32-K32 -> 102.03
A36: Cummulative Profit loss | L36: =L35 -> 102.03

Sheet Summary
B1: =Week1!A12 -> Owned Market Value
B2: Week 1 | C2: Week 2 | D2: Week 3 | E2: Week 4 | F2: Week 5 | G2: Week 6 | H2: Week 7 | I2: Week 8 | J2: Week 9
A3: Week 1 | B3: =Week1!C12 -> 9042.192 | C3: =Week1!D12 -> 9212.346 | D3: =Week1!E12 -> 9240.471 | E3: =Week1!F12 -> 8969.058 | F3: =Week1!G12 -> 9032.346 | G3: =Week1!H12 -> 8841.096 | H3: =Week1!I12 -> 8755.308 | I3: =Week1!J12 -> 8983.125 | J3: =Week1!K12 -> 8873.442
A4: Week 2 | C4: =Week2!E10 -> 9960 | D4: =Week2!F10 -> 9585 | E4: =Week2!G10 -> 9797.5 | F4: =Week2!H10 -> 9927.5 | G4: =Week2!I10 -> 9727.5 | H4: =Week2!J10 -> 9587.5 | I4: =Week2!K10 -> 9387.5 | J4: =Week2!L10 -> 9605
A5: Week 3 | D5: =Week3!F12 -> 9475.5 | E5: =Week3!G12 -> 9663.6 | F5: =Week3!H12 -> 9961.8 | G5: =Week3!I12 -> 9733.5 | H5: =Week3!J12 -> 9859.8 | I5: =Week3!K12 -> 9790.2 | J5: =Week3!L12 -> 9710.7
A6: Week 4 | E6: =Week4!G8 -> 8390 | F6: =Week4!H8 -> 10160 | G6: =Week4!I8 -> 10255 | H6: =Week4!J8 -> 9120 | I6: =Week4!K8 -> 11070 | J6: =Week4!L8 -> 12805
A7: Week 5 | F7: =Week5!H19 -> 10000 | G7: =Week5!I19 -> 10818.036 | H7: =Week5!J19 -> 10477.818 | I7: =Week5!K19 -> 10335.198 | J7: =Week5!L19 -> 10432.075
A8: Week 6 | G8: =Week6!I19 -> 10000 | H8: =Week6!J19 -> 9319.7016 | I8: =Week6!K19 -> 9957.4925 | J8: =Week6!L19 -> 9527.5724
A9: Week 7 | H9: =Week7!J10 -> 8325.9 | I9: =Week7!K10 -> 8527.5 | J9: =Week7!L10 -> 8684.1
A10: Week 8 | I10: =Week8!K10 -> 9814 | J10: =Week8!L10 -> 9748
A11: Total investment | B11: =B3 -> 9042.192 | C11: =B11+C4 -> 19002.192 | D11: =C11+D5 -> 28477.692 | E11: =D11+E6 -> 36867.692 | F11: =E11+F7 -> 46867.692 | G11: =F11+G8 -> 56867.692 | H11: =G11+H9 -> 65193.592 | I11: =H11+I10 -> 75007.592 | J11: =I11 -> 75007.592
A13: Portfolio value | B13: =SUM(B3:B10) -> 9042.192 | C13: =SUM(C3:C10) -> 19172.346 | D13: =SUM(D3:D10) -> 28300.971 | E13: =SUM(E3:E10) -> 36820.158 | F13: =SUM(F3:F10) -> 49081.646 | G13: =SUM(G3:G10) -> 59375.132 | H13: =SUM(H3:H10) -> 65446.028 | I13: =SUM(I3:I10) -> 77865.015 | J13: =SUM(J3:J10) -> 79385.889
A15: Weekly profit or loss | C15: =C13-C11 -> 170.154 | D15: =D16-C15 -> -346.875 | E15: =E16-D15 -> 299.341 | F15: =F16-E15 -> 1914.613 | G15: =G16-F15 -> 592.82665 | H15: =H16-G15 -> -340.39071 | I15: =I16-H15 -> 3197.8141 | J15: =J16-I15 -> 1180.4829
A16: Total profit or Loss | C16: =C13-C11 -> 170.154 | D16: =D13-D11 -> -176.721 | E16: =E13-E11 -> -47.534 | F16: =F13-F11 -> 2213.954 | G16: =G13-G11 -> 2507.4397 | H16: =H13-H11 -> 252.43594 | I16: =I13-I11 -> 2857.4234 | J16: =J13-J11 -> 4378.297
A18: Weekly Rate of return | C18: =C15/C11 -> 0.0089544406 | D18: =D15/D11 -> -0.012180587 | E18: =E15/E11 -> 0.0081193311 | F18: =F15/F11 -> 0.040851446 | G18: =G15/G11 -> 0.010424665 | H18: =H15/H11 -> -0.0052212296 | I18: =I15/I11 -> 0.042633206 | J18: =J15/J11 -> 0.015738179 | L18: Variance | M18: =VAR(C18:J18) -> 0.0003815265
A19: Mean porfolio value | C19: =AVERAGE(B13:J13) -> 47165.486 | D19: =C19 -> 47165.486 | E19: =D19 -> 47165.486 | F19: =E19 -> 47165.486 | G19: =F19 -> 47165.486 | H19: =G19 -> 47165.486 | I19: =H19 -> 47165.486 | J19: =I19 -> 47165.486
A20: Mean absolute return | C20: =C18*C19 -> 422.34055 | D20: =D18*D19 -> -574.5033 | E20: =E18*E19 -> 382.9522 | F20: =F18*F19 -> 1926.7783 | G20: =G18*G19 -> 491.68441 | H20: =H18*H19 -> -246.26183 | I20: =I18*I19 -> 2010.8159 | J20: =J18*J19 -> 742.29885
A21: fed cost of funds monthly | C21: =(1.035)^(1/52)-1 -> 0.00066178478 | D21: =(1.035)^(1/52)-1 -> 0.00066178478 | E21: =(1.035)^(1/52)-1 -> 0.00066178478 | F21: =(1.035)^(1/52)-1 -> 0.00066178478 | G21: =(1.035)^(1/52)-1 -> 0.00066178478 | H21: =(1.035)^(1/52)-1 -> 0.00066178478 | I21: =(1.035)^(1/52)-1 -> 0.00066178478 | J21: =(1.035)^(1/52)-1 -> 0.00066178478
A22: Net return | C22: =C18-C21 -> 0.0082926558 | D22: =D18-D21 -> -0.012842372 | E22: =E18-E21 -> 0.0074575464 | F22: =F18-F21 -> 0.040189661 | G22: =G18-G21 -> 0.0097628805 | H22: =H18-H21 -> -0.0058830143 | I22: =I18-I21 -> 0.041971421 | J22: =J18-J21 -> 0.015076394 | L22: average net return | M22: =AVERAGE(C22:J22) -> 0.013003147
A23: total nest retrun | C23: =C19*C22 -> 391.12715 | D23: =D19*D22 -> -605.7167 | E23: =E19*E22 -> 351.7388 | F23: =F19*F22 -> 1895.5649 | G23: =G19*G22 -> 460.47101 | H23: =H19*H22 -> -277.47523 | I23: =I19*I22 -> 1979.6025 | J23: =J19*J22 -> 711.08545
L25: Sharpe ratio | M25: =M22/M18 -> 34.081897
A27: YOUR RESULTS
B29: Week 1 | C29: Week 2 | D29: Week 3 | E29: Week 4 | F29: Week 5 | G29: Week 6 | H29: Week 7 | I29: Week 8 | J29: Week 9
A30: Week 1 | B30: =Week1!C35 -> 9969 | C30: =Week1!D35 -> 9980 | D30: =Week1!E35 -> 9950 | E30: =Week1!F35 -> 9968 | F30: =Week1!G35 -> 9984 | G30: =Week1!H35 -> 10015 | H30: =Week1!I35 -> 10010.7 | I30: =Week1!J35 -> 10005.4 | J30: =Week1!K35 -> 9984
A31: Week 2 | C31: =Week2!E33 -> 9946.22 | D31: =Week2!F33 -> 9958.61 | E31: =Week2!G33 -> 8825.81 | F31: =Week2!H33 -> 8544.38 | G31: =Week2!I33 -> 7898.92 | H31: =Week2!J33 -> 7616.9 | I31: =Week2!K33 -> 8567.39 | J31: =Week2!L33 -> 9268.31
A32: Week 3 | D32: =Week3!F41 -> 9990.39 | E32: =Week3!G41 -> 9787.77 | F32: =Week3!H41 -> 9180.55 | G32: =Week3!I41 -> 9328.7 | H32: =Week3!J41 -> 9279.8 | I32: =Week3!K41 -> 8995.93 | J32: =Week3!L41 -> 8966
A33: Week 4 | E33: =Week4!G36 -> 9997.03 | F33: =Week4!H36 -> 9695.62 | G33: =Week4!I36 -> 8738.85 | H33: =Week4!J36 -> 8939.27 | I33: =Week4!K36 -> 8979.4 | J33: =Week4!L36 -> 9134.71
A34: Week 5 | F34: =Week5!H46 -> 10000 | G34: =Week5!I46 -> 9679.4359 | H34: =Week5!J46 -> 9026.6861 | I34: =Week5!K46 -> 9271.1061 | J34: =Week5!L46 -> 11197.546
A35: Week 6 | G35: =Week6!I45 -> 10000 | H35: =Week6!J45 -> 8767.594 | I35: =Week6!K45 -> 10449.858 | J35: =Week6!L45 -> 11608.372
A36: Week 7 | H36: =Week7!J34 -> 9955.53 | I36: =Week7!K34 -> 11478.26 | J36: =Week7!L34 -> 11100.435
A37: Week 8 | I37: =Week8!K32 -> 9964.93 | J37: =Week8!L32 -> 10066.96
A38: Total investment | C38: =C31+B40 -> 19915.22 | D38: =D32+C40 -> 29916.61 | E38: =E33+D40 -> 39896.03 | F38: =F34+E40 -> 48578.61 | G38: =G35+F40 -> 57404.55 | H38: =H36+G40 -> 65616.436 | I38: =I37+H40 -> 73561.41 | J38: =I38 -> 73561.41
A40: Portfolio value | B40: =SUM(B30:B37) -> 9969 | C40: =SUM(C30:C37) -> 19926.22 | D40: =SUM(D30:D37) -> 29899 | E40: =SUM(E30:E37) -> 38578.61 | F40: =SUM(F30:F37) -> 47404.55 | G40: =SUM(G30:G37) -> 55660.906 | H40: =SUM(H30:H37) -> 63596.48 | I40: =SUM(I30:I37) -> 77712.274 | J40: =SUM(J30:J37) -> 81326.333
A42: Weekly profit or loss | C42: =C40-C38 -> 11 | D42: =D43-C42 -> -28.61 | E42: =E43-D42 -> -1288.81 | F42: =F43-E42 -> 114.75 | G42: =G43-F42 -> -1858.3941 | H42: =H43-G42 -> -161.56173 | I42: =I43-H42 -> 4312.4259 | J42: =J43-I42 -> 3452.4974
A43: Total profit or Loss | C43: =C40-C38 -> 11 | D43: =D40-D38 -> -17.61 | E43: =E40-E38 -> -1317.42 | F43: =F40-F38 -> -1174.06 | G43: =G40-G38 -> -1743.6441 | H43: =H40-H38 -> -2019.9558 | I43: =I40-I38 -> 4150.8642 | J43: =J40-J38 -> 7764.9233
A45: Weekly Rate of return | C45: =C42/C38 -> 0.00055234138 | D45: =D42/D38 -> -0.00095632493 | E45: =E42/E38 -> -0.032304217 | F45: =F42/F38 -> 0.0023621507 | G45: =G42/G38 -> -0.032373638 | H45: =H42/H38 -> -0.0024622144 | I45: =I42/I38 -> 0.058623481 | J45: =J42/J38 -> 0.046933541 | L45: Variance | M45: =VAR(C45:J45) -> 0.0010771682
A46: Mean porfolio value | C46: =AVERAGE($B$40:$J$40) -> 47119.264 | D46: =AVERAGE($B$40:$J$40) -> 47119.264 | E46: =AVERAGE($B$40:$J$40) -> 47119.264 | F46: =AVERAGE($B$40:$J$40) -> 47119.264 | G46: =AVERAGE($B$40:$J$40) -> 47119.264 | H46: =AVERAGE($B$40:$J$40) -> 47119.264 | I46: =AVERAGE($B$40:$J$40) -> 47119.264 | J46: =AVERAGE($B$40:$J$40) -> 47119.264
A47: Mean absolute return | C47: =C46*C45 -> 26.025919 | D47: =D46*D45 -> -45.061327 | E47: =E46*E45 -> -1522.1509 | F47: =F46*F45 -> 111.3028 | G47: =G46*G45 -> -1525.422 | H47: =H46*H45 -> -116.01773 | I47: =I46*I45 -> 2762.2952 | J47: =J46*J45 -> 2211.4739
A48: fed cost of funds monthly | C48: =(1.035)^(1/52)-1 -> 0.00066178478 | D48: =(1.035)^(1/52)-1 -> 0.00066178478 | E48: =(1.035)^(1/52)-1 -> 0.00066178478 | F48: =(1.035)^(1/52)-1 -> 0.00066178478 | G48: =(1.035)^(1/52)-1 -> 0.00066178478 | H48: =(1.035)^(1/52)-1 -> 0.00066178478 | I48: =(1.035)^(1/52)-1 -> 0.00066178478 | J48: =(1.035)^(1/52)-1 -> 0.00066178478
A49: Net return | C49: =C45-C48 -> -0.00010944341 | D49: =D45-D48 -> -0.0016181097 | E49: =E45-E48 -> -0.032966002 | F49: =F45-F48 -> 0.001700366 | G49: =G45-G48 -> -0.033035422 | H49: =H45-H48 -> -0.0031239992 | I49: =I45-I48 -> 0.057961696 | J49: =J45-J48 -> 0.046271756 | L49: average net return | M49: =AVERAGE(C49:J49) -> 0.0043851052
...
